Workbook
Name pivot1: 'pivot and charts'!$A$3:$B$12
Name Slicer_Customer_Type: #N/A
Name Slicer_Month: #N/A
Name Slicer_Payment_Method: #N/A
Name Slicer_Region: #N/A

Sheet uncleaned_sales data
A1: Order ID | B1: Date | C1: Salesperson | D1: Region | E1: Category | F1: Product Name | G1: Units Sold | H1: Unit Price (PKR) | I1: Discount % | J1: Total Revenue (PKR) | K1: Cost Price (Unit) | L1: Total Cost (PKR) | M1: Customer Type | N1: Payment Method | O1: Delivery Status
A2: ORD-1002 | B2: 2024-10-06 | C2: Sara Khan | D2: Faisalabad | E2: Electronics | F2: Mobile Phone | G2: 3 | H2: 25000 | I2: 5 | J2: 71250 | K2: 18000 | L2: 54000 | N2: EasyPaisa | O2: Pending
A3: ORD-1005 | B3: 2024-06-25 | C3: Nadia Iqbal | D3: Quetta | E3: Electronics | F3: Headphones | H3: 5000 | I3: 0 | J3: 90000 | K3: 3000 | L3: 54000 | M3: Returning | N3: Cash | O3: Delivered
A4: ORD-1012 | B4: 2024-03-11 | C4: Kamran Sheikh | D4: Rawalpindi | E4: Electronics | F4: Mobile Phone | G4: 4 | H4: 25000 | I4: 5 | J4: 95000 | K4: 18000 | L4: 72000 | M4: New | N4: Bank Transfer | O4: Delivered
A5: ORD-1021 | B5: 2024-11-19 | C5: Ahmed Ali | D5: Peshawar | E5: Electronics | F5: Mobile Phone | G5: 11 | H5: 25000 | I5: 0 | J5: 275000 | K5: 18000 | L5: 198000 | M5: New | N5: Debit Card | O5: Pending
A6: ORD-1026 | B6: 2024-11-29 | C6: Kamran Sheikh | D6: Karachi | E6: Electronics | F6: Laptop | G6: 6 | H6: 85000 | I6: 15 | J6: 433500 | K6: 65000 | L6: 390000 | M6: Returning | N6: JazzCash | O6: Delivered
A7: ORD-1030 | B7: 2024-02-04 | C7: Fatima Malik | D7: Faisalabad | E7: Electronics | F7: Smartwatch | G7: 8 | H7: 15000 | I7: 20 | J7: 96000 | K7: 10000 | L7: 80000 | M7: New | N7: EasyPaisa | O7: Delivered
A8: ORD-1041 | B8: 2024-05-07 | C8: Usman Raza | D8: Karachi | E8: Electronics | F8: Headphones | G8: 2 | H8: 5000 | I8: 15 | J8: 8500 | K8: 3000 | L8: 6000 | M8: New | N8: Credit Card | O8: Shipped
A9: ORD-1044 | B9: 2024-05-13 | C9: Bilal Hussain | D9: Quetta | E9: Electronics | F9: Mobile Phone | G9: 20 | H9: 25000 | I9: 15 | J9: 425000 | K9: 18000 | L9: 360000 | M9: Returning | N9: Bank Transfer | O9: Shipped
A10: ORD-1051 | B10: 2024-04-11 | C10: Bilal Hussain | D10: Karachi | E10: Electronics | F10: Laptop | G10: 16 | H10: 85000 | I10: 20 | J10: 1088000 | K10: 65000 | L10: 1040000 | M10: New | N10: JazzCash | O10: Delivered
A11: ORD-1057 | B11: 2024-12-21 | C11: Bilal Hussain | D11: Karachi | E11: Electronics | F11: Headphones | G11: 14 | H11: 5000 | I11: 10 | J11: 63000 | K11: 3000 | L11: 42000 | M11: Returning | N11: JazzCash | O11: Delivered
A12: ORD-1066 | B12: 2024-07-11 | C12: Hassan Mirza | D12: Peshawar | E12: Electronics | F12: Smartwatch | G12: 8 | H12: 15000 | I12: 0 | J12: 120000 | K12: 10000 | L12: 80000 | M12: Returning | N12: Bank Transfer
A13: ORD-1088 | B13: 2024-08-09 | C13: Ayesha Siddiqui | D13: Quetta | E13: Electronics | F13: Mobile Phone | G13: 8 | H13: 25000 | I13: 25 | J13: 150000 | K13: 18000 | L13: 144000 | M13: New | N13: Bank Transfer | O13: Shipped
A14: ORD-1095 | B14: 2024-04-25 | C14: Sara Khan | D14: Rawalpindi | E14: Electronics | F14: Laptop | G14: 16 | H14: 85000 | I14: 25 | J14: 1020000 | K14: 65000 | L14: 1040000 | M14: Returning | N14: EasyPaisa | O14: Pending
A15: ORD-1101 | B15: 2024-03-05 | C15: Kamran Sheikh | D15: Multan | E15: Electronics | F15: laptop | G15: 4 | H15: 5000 | I15: 20 | J15: 16000 | K15: 3000 | L15: 12000 | M15: Returning | O15: Pending
A16: ORD-1105 | B16: 2024-01-15 | C16: Ahmed Ali | D16: Multan | E16: Electronics | F16: laptop | G16: 12 | H16: 35000 | I16: 10 | J16: 378000 | K16: 26000 | L16: 312000 | M16: Returning | N16: Credit Card | O16: Delivered
A17: ORD-1108 | B17: 2024-08-26 | C17: Usman Raza | D17: Islamabad | E17: Electronics | F17: Headphones | G17: 12 | H17: 5000 | I17: 20 | J17: 48000 | K17: 3000 | L17: 36000 | M17: Returning | N17: Bank Transfer | O17: Cancelled
A18: ORD-1112 | B18: 2024-05-08 | C18: Bilal Hussain | D18: Lahor | E18: Electronics | F18: Tablet | G18: 15 | H18: 35000 | I18: 0 | J18: 525000 | K18: 26000 | L18: 390000 | M18: Returning | N18: Bank Transfer | O18: Delivered
A19: ORD-1115 | B19: 2024-04-25 | C19: Hassan Mirza | D19: Multan | E19: Electronics | F19: Headphones | G19: 1 | H19: 5000 | I19: 10 | J19: 4500 | K19: 3000 | L19: 3000 | N19: JazzCash | O19: Delivered
A20: ORD-1117 | B20: 2024-10-14 | C20: Ayesha Siddiqui | D20: Peshawar | E20: Electronics | F20: Headphones | G20: 10 | H20: 5000 | I20: 25 | J20: 37500 | K20: 3000 | L20: 30000 | M20: Returning | N20: Cash | O20: Delivered
A21: ORD-1118 | B21: 2024-01-20 | C21: Usman Raza | D21: Rawalpindi | E21: Electronics | F21: Mobile Phone | G21: 8 | H21: 25000 | I21: 20 | J21: 160000 | K21: 18000 | L21: 144000 | M21: New | N21: JazzCash | O21: Delivered
A22: ORD-1121 | B22: 2024-07-07 | C22: Kamran Sheikh | D22: Multan | E22: Electronics | F22: laptop | G22: 9 | H22: 5000 | J22: 42750 | K22: 3000 | L22: 27000 | M22: New | N22: JazzCash | O22: Delivered
A23: ORD-1122 | B23: 2024-04-18 | C23: Nadia Iqbal | D23: Karachi | E23: Electronics | F23: Tablet | G23: 8 | H23: 35000 | I23: 5 | J23: 266000 | K23: 26000 | L23: 208000 | M23: New | N23: Cash | O23: Shipped
A24: ORD-1125 | B24: 2024-05-01 | C24: Nadia Iqbal | D24: Multan | E24: Electronics | F24: Laptop | G24: 9 | H24: 85000 | I24: 0 | J24: 765000 | K24: 65000 | L24: 585000 | M24: New | N24: Bank Transfer | O24: Delivered
A25: ORD-1128 | B25: 2024-09-08 | C25: Zara Butt | D25: Lahore | E25: Electronics | F25: Tablet | G25: 20 | H25: 35000 | I25: 5 | J25: 665000 | K25: 26000 | L25: 520000 | M25: New | N25: Credit Card | O25: Delivered
A26: ORD-1132 | B26: 2024-02-13 | C26: Sara Khan | D26: Faisalabad | E26: Electronics | F26: Tablet | G26: 5 | H26: 35000 | I26: 20 | J26: 140000 | K26: 26000 | L26: 130000 | M26: New | O26: Cancelled
A27: ORD-1137 | B27: 2024-03-14 | C27: Nadia Iqbal | D27: Faisalabad | E27: Electronics | F27: Laptop | G27: 1 | H27: 85000 | I27: 0 | J27: 85000 | K27: 65000 | L27: 65000 | M27: New | N27: JazzCash | O27: Delivered
A28: ORD-1142 | B28: 2024-05-10 | C28: Usman Raza | D28: Multan | E28: Electronics | F28: Mobile Phone | G28: 16 | H28: 25000 | I28: 25 | J28: 300000 | K28: 18000 | L28: 288000 | M28: Returning | N28: Credit Card | O28: Delivered
A29: ORD-1143 | B29: 2024-09-29 | C29: Fatima Malik | D29: Multan | E29: Electronics | F29: Headphones | G29: 2 | H29: 5000 | I29: 15 | J29: 8500 | K29: 3000 | L29: 6000 | M29: New | N29: JazzCash | O29: Cancelled
A30: ORD-1148 | B30: 2024-03-29 | C30: Nadia Iqbal | D30: Islamabad | E30: Electronics | F30: Laptop | G30: 16 | H30: 85000 | I30: 15 | J30: 1156000 | K30: 65000 | L30: 1040000 | M30: Returning | N30: Bank Transfer | O30: Cancelled
A31: ORD-1151 | B31: 2024-07-07 | C31: Usman Raza | D31: Lahore | E31: Electronics | F31: Smartwatch | G31: 20 | H31: 15000 | I31: 20 | J31: 240000 | K31: 10000 | L31: 200000 | M31: Returning | N31: JazzCash | O31: Delivered
A32: ORD-1153 | B32: 2024-06-24 | C32: Sara Khan | D32: Islamabad | E32: Electronics | F32: Laptop | G32: 15 | H32: 85000 | I32: 15 | J32: 1083750 | K32: 65000 | L32: 975000 | M32: New | O32: Delivered
A33: ORD-1164 | B33: 2024-09-19 | C33: Bilal Hussain | D33: Faisalabad | E33: Electronics | F33: Laptop | H33: 85000 | I33: 10 | J33: 1147500 | K33: 65000 | L33: 975000 | M33: New | N33: JazzCash | O33: Delivered
A34: ORD-1167 | B34: 2024-11-11 | C34: Ahmed Ali | D34: Lahore | E34: Electronics | F34: Tablet | G34: 7 | H34: 35000 | I34: 5 | J34: 232750 | K34: 26000 | L34: 182000 | N34: Cash | O34: Shipped
A35: ORD-1168 | B35: 2024-05-01 | C35: Usman Raza | D35: Lahore | E35: Electronics | F35: Laptop | H35: 85000 | I35: 25 | J35: 892500 | K35: 65000 | L35: 910000 | M35: Returning | N35: Cash | O35: Delivered
A36: ORD-1175 | B36: 2024-10-05 | C36: Zara Butt | D36: Quetta | E36: Electronics | F36: Laptop | G36: 10 | H36: 85000 | I36: 10 | J36: 765000 | K36: 65000 | L36: 650000 | M36: New | N36: Bank Transfer | O36: Delivered
A37: ORD-1177 | B37: 2024-07-07 | C37: Kamran Sheikh | D37: Quetta | E37: Electronics | F37: Headphones | G37: 3 | H37: 5000 | I37: 15 | J37: 12750 | K37: 3000 | L37: 9000 | M37: New | N37: EasyPaisa | O37: Delivered
A38: ORD-1180 | B38: 2024-07-26 | C38: Ayesha Siddiqui | D38: Islamabad | E38: Electronics | F38: Laptop | G38: 20 | H38: 85000 | I38: 25 | J38: 1275000 | K38: 65000 | L38: 1300000 | M38: Returning | N38: Cash | O38: Delivered
A39: ORD-1182 | B39: 2024-07-08 | C39: Ayesha Siddiqui | D39: Rawalpindi | E39: Electronics | F39: Smartwatch | G39: 5 | H39: 15000 | I39: 20 | J39: 60000 | K39: 10000 | L39: 50000 | M39: Returning | N39: JazzCash | O39: Delivered
A40: ORD-1183 | B40: 2024-05-22 | C40: Fatima Malik | D40: Lahore | E40: Electronics | F40: Laptop | G40: 16 | H40: 85000 | I40: 20 | J40: 1088000 | K40: 65000 | L40: 1040000 | M40: Returning | N40: EasyPaisa | O40: Delivered
...

Sheet clean_sales data
A1: Order ID | B1: Date | C1: Salesperson | D1: Region | E1: Category | F1: Product Name | G1: Units Sold | H1: Unit Price (PKR) | I1: Discount % | J1: Total Revenue (PKR) | K1: Cost Price (Unit) | L1: Total Cost (PKR) | M1: Profit (PKR) | N1: Margin | O1: Customer Type | P1: Payment Method | Q1: Delivery Status | R1: Month
A2: ORD-1002 | B2: 2024-10-06 | C2: Sara Khan | D2: Faisalabad | E2: Electronics | F2: Mobile Phone | G2: 3 | H2: 25000 | I2: 5 | J2: 71250 | K2: 18000 | L2: 54000 | M2: 17250 | N2: =M2/J2 -> 0.24210526 | O2: New | P2: EasyPaisa | Q2: Pending | R2: =TEXT(B2,"MMM") -> Oct
A3: ORD-1005 | B3: 2024-06-25 | C3: Nadia Iqbal | D3: Quetta | E3: Electronics | F3: Headphones | G3: 18 | H3: 5000 | I3: 0 | J3: 90000 | K3: 3000 | L3: 54000 | M3: 36000 | N3: =M3/J3 -> 0.4 | O3: Returning | P3: Cash | Q3: Delivered | R3: =TEXT(B3,"MMM") -> Jun
A4: ORD-1012 | B4: 2024-03-11 | C4: Kamran Sheikh | D4: Rawalpindi | E4: Electronics | F4: Mobile Phone | G4: 4 | H4: 25000 | I4: 5 | J4: 95000 | K4: 18000 | L4: 72000 | M4: 23000 | N4: =M4/J4 -> 0.24210526 | O4: New | P4: Bank Transfer | Q4: Delivered | R4: =TEXT(B4,"MMM") -> Mar
A5: ORD-1021 | B5: 2024-11-19 | C5: Ahmed Ali | D5: Peshawar | E5: Electronics | F5: Mobile Phone | G5: 11 | H5: 25000 | I5: 0 | J5: 275000 | K5: 18000 | L5: 198000 | M5: 77000 | N5: =M5/J5 -> 0.28 | O5: New | P5: Debit Card | Q5: Pending | R5: =TEXT(B5,"MMM") -> Nov
A6: ORD-1026 | B6: 2024-11-29 | C6: Kamran Sheikh | D6: Karachi | E6: Electronics | F6: Laptop | G6: 6 | H6: 85000 | I6: 15 | J6: 433500 | K6: 65000 | L6: 390000 | M6: 43500 | N6: =M6/J6 -> 0.10034602 | O6: Returning | P6: JazzCash | Q6: Delivered | R6: =TEXT(B6,"MMM") -> Nov
A7: ORD-1030 | B7: 2024-02-04 | C7: Fatima Malik | D7: Faisalabad | E7: Electronics | F7: Smartwatch | G7: 8 | H7: 15000 | I7: 20 | J7: 96000 | K7: 10000 | L7: 80000 | M7: 16000 | N7: =M7/J7 -> 0.16666667 | O7: New | P7: EasyPaisa | Q7: Delivered | R7: =TEXT(B7,"MMM") -> Feb
A8: ORD-1041 | B8: 2024-05-07 | C8: Usman Raza | D8: Islamabad | E8: Electronics | F8: Headphones | G8: 2 | H8: 5000 | I8: 15 | J8: 8500 | K8: 3000 | L8: 6000 | M8: 2500 | N8: =M8/J8 -> 0.29411765 | O8: New | P8: Credit Card | Q8: Shipped | R8: =TEXT(B8,"MMM") -> May
A9: ORD-1044 | B9: 2024-05-13 | C9: Bilal Hussain | D9: Quetta | E9: Electronics | F9: Mobile Phone | G9: 20 | H9: 25000 | I9: 15 | J9: 425000 | K9: 18000 | L9: 360000 | M9: 65000 | N9: =M9/J9 -> 0.15294118 | O9: Returning | P9: Bank Transfer | Q9: Shipped | R9: =TEXT(B9,"MMM") -> May
A10: ORD-1051 | B10: 2024-04-11 | C10: Bilal Hussain | D10: Karachi | E10: Electronics | F10: Laptop | G10: 16 | H10: 85000 | I10: 20 | J10: 1088000 | K10: 65000 | L10: 1040000 | M10: 48000 | N10: =M10/J10 -> 0.044117647 | O10: New | P10: JazzCash | Q10: Delivered | R10: =TEXT(B10,"MMM") -> Apr
A11: ORD-1057 | B11: 2024-12-21 | C11: Bilal Hussain | D11: Peshawar | E11: Electronics | F11: Headphones | G11: 14 | H11: 5000 | I11: 10 | J11: 63000 | K11: 3000 | L11: 42000 | M11: 21000 | N11: =M11/J11 -> 0.33333333 | O11: Returning | P11: JazzCash | Q11: Delivered | R11: =TEXT(B11,"MMM") -> Dec
A12: ORD-1066 | B12: 2024-07-11 | C12: Hassan Mirza | D12: Peshawar | E12: Electronics | F12: Smartwatch | G12: 8 | H12: 15000 | I12: 0 | J12: 120000 | K12: 10000 | L12: 80000 | M12: 40000 | N12: =M12/J12 -> 0.33333333 | O12: Returning | P12: Bank Transfer | Q12: Pending | R12: =TEXT(B12,"MMM") -> Jul
A13: ORD-1088 | B13: 2024-08-09 | C13: Ayesha Siddiqui | D13: Quetta | E13: Electronics | F13: Mobile Phone | G13: 8 | H13: 25000 | I13: 25 | J13: 150000 | K13: 18000 | L13: 144000 | M13: 6000 | N13: =M13/J13 -> 0.04 | O13: New | P13: Bank Transfer | Q13: Shipped | R13: =TEXT(B13,"MMM") -> Aug
... A90: ORD-1495 | B90: 2024-01-19 | C90: Ayesha Siddiqui | D90: Peshawar | E90: Electronics | F90: Laptop | G90: 3 | H90: 85000 | I90: 10 | J90: 229500 | K90: 65000 | L90: 195000 | M90: 34500 | N90: =M90/J90 -> 0.1503268 | O90: Returning | P90: Debit Card | Q90: Pending | R90: =TEXT(B90,"MMM") -> Jan

Sheet pivot and charts
J22: Region | K22: Sum of Total Revenue (PKR)
E23: =GETPIVOTDATA("Total Revenue (PKR)",$A$31,"Month","Dec") -> 3896000 | G23: =GETPIVOTDATA("Total Revenue (PKR)",$A$31,"Month","Jan") -> 1320000 | J23: Lahore | K23: 5986250
J24: Multan | K24: 4882500
E25: CAGR | F25: =(E23/G23)^(1/12)-1 -> 0.094385721 | H25: =(E23/G23)^(1/12)-1 -> 0.094385721 | J25: Karachi | K25: 4551000
J26: Islamabad | K26: 4516000
J27: Rawalpindi | K27: 4098500
E28: =GETPIVOTDATA("Total Revenue (PKR)",$A$31,"Month","Jan") -> 1320000 | J28: Faisalabad | K28: 3858500
J29: Quetta | K29: 2803250
J30: Peshawar | K30: 2626000
A31: Month | B31: Sum of Total Revenue (PKR) | J31: Grand Total | K31: 33322000
A32: Jan | B32: 1320000 | U32: =GETPIVOTDATA("Total Revenue (PKR)",'pivot and charts'!$A$87)+'pivot and charts'!A86 -> 33322000
A33: Feb | B33: 1092750
A34: Mar | B34: 4213000
A35: Apr | B35: 3602500
A36: May | B36: 4013500
A37: Jun | B37: 1304500
A38: Jul | B38: 2040000
A39: Aug | B39: 2193500
A40: Sep | B40: 4219500
A41: Oct | B41: 2615750
A42: Nov | B42: 2811000
A43: Dec | B43: 3896000
A44: Grand Total | B44: 33322000
A52: Payment Method | B52: Count of Payment Method
A53: EasyPaisa | B53: 0.20224719
A54: Bank Transfer | B54: 0.19101124
A55: JazzCash | B55: 0.17977528
A56: Credit Card | B56: 0.15730337
A57: Cash | B57: 0.15730337
A58: Debit Card | B58: 0.11235955 | K58: Salesperson | L58: Sum of Total Revenue (PKR)
A59: Grand Total | B59: 1 | K59: Ahmed Ali | L59: 2053250
K60: Ayesha Siddiqui | L60: 4581500
K61: Bilal Hussain | L61: 6373000
K62: Fatima Malik | L62: 4111250
K63: Hassan Mirza | L63: 1099000
K64: Kamran Sheikh | L64: 1004750
K65: Nadia Iqbal | L65: 4337750
K66: Sara Khan | L66: 4315500
K67: Usman Raza | L67: 2618000
K68: Zara Butt | L68: 2828000
...

Sheet Dashboard
F6: totagsahsbasbas
D43: =GETPIVOTDATA("Units Sold",'pivot and charts'!$A$92) -> 925 | E43: =GETPIVOTDATA("Margin",'pivot and charts'!$C$92) -> 0.17679671 | F43: =GETPIVOTDATA("Total Revenue (PKR)",'pivot and charts'!$A$87) -> 33322000 | H43: =GETPIVOTDATA("Profit (PKR)",'pivot and charts'!$C$87) -> 3604000
